Workbook
Name NativeTimeline_Date: #N/A
Name Slicer_Customer_Name: #N/A
Name Slicer_Months__Timestamp: #N/A
Name Slicer_Select__Set_Categories: #N/A
Name Slicer_Service_item_category: #N/A
Name Slicer_Unit_Price_per_crate: #N/A
Name Slicer_Years__Timestamp: #N/A

Sheet Egg sorting&grading
A1: Timestamp | B1: COLLECTION DATE | C1: Select SET | D1: Select Size | E1: Number of crates | F1: Number of singles(pcs) | G1: Do you still have some more data to record
A2: 46055.332 | B2: 46054 | C2: SET A | D2: S - (45 GHS) | E2: 0 | F2: 10
A3: 46055.332 | B3: 46054 | C3: SET A | D3: M - (50 GHS) | E3: 0 | F3: 17
A4: 46055.333 | B4: 46054 | C4: SET A | D4: L - (55 GHS) | E4: 0 | F4: 23
A5: 46055.333 | B5: 46054 | C5: SET A | D5: XL - (60 GHS) | E5: 0 | F5: 5
A6: 46055.333 | B6: 46054 | C6: SET B | D6: XS - (40 GHS) | E6: 0 | F6: 13
A7: 46055.334 | B7: 46054 | C7: SET B | D7: S - (45 GHS) | E7: 2 | F7: 29
A8: 46055.334 | B8: 46054 | C8: SET B | D8: M - (50 GHS) | E8: 6 | F8: 6
A9: 46055.334 | B9: 46054 | C9: SET B | D9: L - (55 GHS) | E9: 4 | F9: 17
A10: 46055.335 | B10: 46054 | C10: SET B | D10: XL - (60 GHS) | E10: 1 | F10: 1
A11: 46055.335 | B11: 46054 | C11: SET C | D11: XS - (40 GHS) | E11: 0 | F11: 24
A12: 46055.335 | B12: 46054 | C12: SET C | D12: S - (45 GHS) | E12: 4 | F12: 17
A13: 46055.336 | B13: 46054 | C13: SET C | D13: M - (50 GHS) | E13: 4 | F13: 9
... A15: 46055.339 | B15: 46054 | C15: SET C | D15: XL - (60 GHS) | E15: 0 | F15: 6

Sheet Sales by Month
A2: Month | B2: (All)
A4: Sum of Amount Paid | B4: Column Labels
A5: Row Labels | B5: 2026 | C5: Grand Total
A6: Jan | B6: 40940 | C6: 40940
A7: Feb | B7: 15750 | C7: 15750
A8: Grand Total | B8: 56690 | C8: 56690
A23: total sales | B23: =GETPIVOTDATA("Amount Paid",$A$4) -> 56690
A24: Profit | B24: =B23-'MOM Expenses'!B25 -> -104784
A30: Month | B30: (All)
A32: Average of Unit Price(per crate) | B32: Column Labels
A33: Row Labels | B33: 2026 | C33: Grand Total
A34: Jan | B34: 48.75 | C34: 48.75
A35: Feb | B35: 48.461538 | C35: 48.461538
A36: Grand Total | B36: 48.677419 | C36: 48.677419
A48: Average Price/crate | B48: =GETPIVOTDATA("Unit Price(per crate)",$A$32) -> 48.677419

Sheet Sales by Size
A1: Months (Date) | B1: (All)
A3: Sum of Amount Paid | B3: Column Labels
A4: Row Labels | B4: 2026 | C4: Grand Total
A5: 40 | B5: 4480 | C5: 4480
A6: 45 | B6: 14535 | C6: 14535
A7: 50 | B7: 20800 | C7: 20800
A8: 55 | B8: 13475 | C8: 13475
A9: 60 | B9: 2100 | C9: 2100
A10: 65 | B10: 1300 | C10: 1300
A11: Grand Total | B11: 56690 | C11: 56690

Sheet Sales by Customer
A1: Month | B1: (All)
A3: Row Labels | B3: Sum of Amount Paid
A4: AB Prime | B4: 150
A5: Aberkuma North K | B5: 3250
A6: Aberkuma North K | B6: 5950
A7: Afriyie Agric | B7: 950
A8: Agya Atta | B8: 50
A9: Amelia Adabraka | B9: 550
A10: Amelia Adabraka | B10: 500
A11: Amelia Kotoku | B11: 200
A12: Amelia Kotoku | B12: 100
A13: Ant Gina | B13: 80
A14: Ant Gina | B14: 120
A15: Ant Lydia | B15: 500
... A84: Grand Total | B84: 56690

Sheet Quantity Sold byMonth
A1: Month | B1: (All)
A3: Sum of Quantity | B3: Column Labels
A4: Row Labels | B4: 2026 | C4: Grand Total
A5: Jan | B5: 836 | C5: 836
A6: Feb | B6: 315 | C6: 315
A7: Grand Total | B7: 1151 | C7: 1151
A19: tootal quantity soldd | B19: =GETPIVOTDATA("Quantity",$A$3) -> 1151

Sheet Egg Sales
A1: Timestamp | B1: Date | C1: Customer Name | D1: Unit Price(per crate) | E1: Quantity | F1: Amount Paid | G1: Payment Channel | H1: Month | I1: Total | J1: Total Pieces | K1: Check | L1: Amount Banked
A2: 46358.229 | B2: 46064 | C2: Martha Akuorkor | D2: 40 | E2: 4 | F2: 160 | H2: 46054 | I2: 160 | J2: 120 | K2: TRUE
A3: 46358.228 | B3: 46064 | C3: Martha Akuorkor | D3: 45 | E3: 6 | F3: 270 | H3: 46054 | I3: 270 | J3: 180 | K3: TRUE
A4: 46297.671 | B4: 46063 | C4: Mummy | D4: 50 | E4: 2 | F4: 100 | H4: 46054 | I4: 100 | J4: 60 | K4: TRUE
A5: 46297.564 | B5: 46063 | C5: Tei | D5: 45 | E5: 4 | F5: 180 | H5: 46054 | I5: 180 | J5: 120 | K5: TRUE
A6: 46297.551 | B6: 46063 | C6: Thasha | D6: 45 | E6: 3 | F6: 135 | H6: 46054 | I6: 135 | J6: 90 | K6: TRUE
A7: 46297.55 | B7: 46063 | C7: Mama Becky | D7: 45 | E7: 2 | F7: 90 | H7: 46054 | I7: 90 | J7: 60 | K7: TRUE
A8: 46297.55 | B8: 46063 | C8: Sis Maggie | D8: 45 | E8: 10 | F8: 450 | H8: 46054 | I8: 450 | J8: 300 | K8: TRUE
A9: 46297.55 | B9: 46063 | C9: Aberkuma North K | D9: 55 | E9: 20 | F9: 1100 | H9: 46054 | I9: 1100 | J9: 600 | K9: TRUE
A10: 46297.548 | B10: 46063 | C10: Aberkuma North K | D10: 50 | E10: 20 | F10: 1000 | H10: 46054 | I10: 1000 | J10: 600 | K10: TRUE
A11: 46267.394 | B11: 46062 | C11: Ice Block Woman | D11: 45 | E11: 3 | F11: 135 | H11: 46054 | I11: 135 | J11: 90 | K11: TRUE
A12: 46267.393 | B12: 46062 | C12: Amelia Kotoku | D12: 50 | E12: 4 | F12: 200 | H12: 46054 | I12: 200 | J12: 120 | K12: TRUE | L12: 15360
A13: 46267.607 | B13: 46061 | C13: Rev Class Peters | D13: 65 | E13: 4 | F13: 260 | H13: 46054 | I13: 260 | J13: 120 | K13: TRUE
A14: 46267.393 | B14: 46061 | C14: Aberkuma North K | D14: 55 | E14: 10 | F14: 550 | H14: 46054 | I14: 550 | J14: 300 | K14: TRUE
A15: 46267.393 | B15: 46061 | C15: Aberkuma North K | D15: 60 | E15: 10 | F15: 600 | H15: 46054 | I15: 600 | J15: 300 | K15: TRUE
A16: 46267.388 | B16: 46061 | C16: Lady Tantra Hill | D16: 50 | E16: 10 | F16: 500 | H16: 46054 | I16: 500 | J16: 300 | K16: TRUE
A17: 46267.386 | B17: 46061 | C17: Moda | D17: 45 | E17: 3 | F17: 135 | H17: 46054 | I17: 135 | J17: 90 | K17: TRUE
A18: 46267.382 | B18: 46061 | C18: Moda's Tenant | D18: 40 | E18: 4 | F18: 160 | H18: 46054 | I18: 160 | J18: 120 | K18: TRUE
A19: 46267.381 | B19: 46061 | C19: Lady | D19: 40 | E19: 2 | F19: 80 | H19: 46054 | I19: 80 | J19: 60 | K19: TRUE
A20: 46267.381 | B20: 46061 | C20: Amelia Adabraka | D20: 55 | E20: 10 | F20: 550 | H20: 46054 | I20: 550 | J20: 300 | K20: TRUE
A21: 46236.345 | B21: 46061 | C21: Wele House | D21: 50 | E21: 10 | F21: 500 | H21: 46054 | I21: 500 | J21: 300 | K21: TRUE
A22: 46205.772 | B22: 46060 | C22: Vanessa | D22: 45 | E22: 3 | F22: 135 | H22: 46054 | I22: 135 | J22: 90 | K22: TRUE
A23: 46205.277 | B23: 46059 | C23: Sis Maggie | D23: 45 | E23: 7 | F23: 315 | H23: 46054 | I23: 315 | J23: 210 | K23: TRUE
A24: 46205.269 | B24: 46059 | C24: Bro DK | D24: 65 | E24: 2 | F24: 130 | H24: 46054 | I24: 130 | J24: 60 | K24: TRUE
... A37: 46055.737 | B37: 46055 | C37: Ice block Woman | D37: 45 | E37: 2 | F37: 90 | H37: 46054 | I37: 90 | J37: 60 | K37: TRUE
A38: 46054.769 | B38: 46054 | C38: Bro Kofi | D38: 50 | E38: 4 | F38: 200 | H38: =TEXT(B38, "MMMM YYYY") -> February 2026 | I38: =D38*E38 -> 200 | J38: =E38*30 -> 120 | K38: =IF(F38=I38,TRUE) -> TRUE
A39: 46055.322 | B39: 46054 | C39: Martha Akuokor | D39: 40 | E39: 4 | F39: 160 | H39: =TEXT(B39, "MMMM YYYY") -> February 2026 | I39: =D39*E39 -> 160 | J39: =E39*30 -> 120 | K39: =IF(F39=I39,TRUE) -> TRUE
A40: 46055.331 | B40: 46054 | C40: Martha Akuokor | D40: 45 | E40: 7 | F40: 315 | H40: =TEXT(B40, "MMMM YYYY") -> February 2026 | I40: =D40*E40 -> 315 | J40: =E40*30 -> 210 | K40: =IF(F40=I40,TRUE) -> TRUE
A41: 46054.455 | B41: 46053 | C41: Vanessa | D41: 50 | E41: 1 | F41: 50 | H41: =TEXT(B41, "MMMM YYYY") -> January 2026 | I41: =D41*E41 -> 50 | J41: =E41*30 -> 30 | K41: =IF(F41=I41,TRUE) -> TRUE
A42: 46054.042 | B42: 46053 | C42: Martha Akuokor | D42: 40 | E42: 3 | F42: 120 | H42: =TEXT(B42, "MMMM YYYY") -> January 2026 | I42: =D42*E42 -> 120 | J42: =E42*30 -> 90 | K42: =IF(F42=I42,TRUE) -> TRUE
A43: 46054.768 | B43: 46053 | C43: Phyllis Amartey | D43: 45 | E43: 10 | F43: 450 | H43: =TEXT(B43, "MMMM YYYY") -> January 2026 | I43: =D43*E43 -> 450 | J43: =E43*30 -> 300 | K43: =IF(F43=I43,TRUE) -> TRUE
A44: 46054.768 | B44: 46053 | C44: Ant Gina | D44: 60 | E44: 2 | F44: 120 | H44: =TEXT(B44, "MMMM YYYY") -> January 2026 | I44: =D44*E44 -> 120 | J44: =E44*30 -> 60 | K44: =IF(F44=I44,TRUE) -> TRUE
A45: 46052.763 | B45: 46052 | C45: Maa J | D45: 65 | E45: 2 | F45: 130 | H45: =TEXT(B45, "MMMM YYYY") -> January 2026 | I45: =D45*E45 -> 130 | J45: =E45*30 -> 60 | K45: =IF(F45=I45,TRUE) -> TRUE
A46: 46052.762 | B46: 46052 | C46: Bubiashie indomie | D46: 50 | E46: 20 | F46: 1000 | H46: =TEXT(B46, "MMMM YYYY") -> January 2026 | I46: =D46*E46 -> 1000 | J46: =E46*30 -> 600 | K46: =IF(F46=I46,TRUE) -> TRUE
A47: 46052.762 | B47: 46052 | C47: Bubiashie Kenkey | D47: 55 | E47: 20 | F47: 1100 | H47: =TEXT(B47, "MMMM YYYY") -> January 2026 | I47: =D47*E47 -> 1100 | J47: =E47*30 -> 600 | K47: =IF(F47=I47,TRUE) -> TRUE
A48: 46052.329 | B48: 46052 | C48: Moses | D48: 40 | E48: 2 | F48: 80 | H48: =TEXT(B48, "MMMM YYYY") -> January 2026 | I48: =D48*E48 -> 80 | J48: =E48*30 -> 60 | K48: =IF(F48=I48,TRUE) -> TRUE
A49: 46051.01 | B49: 46050 | C49: Haajii Anye | D49: 45 | E49: 20 | F49: 900 | H49: =TEXT(B49, "MMMM YYYY") -> January 2026 | I49: =D49*E49 -> 900 | J49: =E49*30 -> 600 | K49: =IF(F49=I49,TRUE) -> TRUE | L49: 7655
A50: 46050.515 | B50: 46050 | C50: Martha Akuokor | D50: 40 | E50: 3 | F50: 120 | H50: =TEXT(B50, "MMMM YYYY") -> January 2026 | I50: =D50*E50 -> 120 | J50: =E50*30 -> 90 | K50: =IF(F50=I50,TRUE) -> TRUE
A51: 46050.513 | B51: 46050 | C51: Deborah Kotoku | D51: 50 | E51: 2 | F51: 100 | H51: =TEXT(B51, "MMMM YYYY") -> January 2026 | I51: =D51*E51 -> 100 | J51: =E51*30 -> 60 | K51: =IF(F51=I51,TRUE) -> TRUE
A52: 46050.513 | B52: 46050 | C52: Deborah Kotoku | D52: 45 | E52: 5 | F52: 225 | H52: =TEXT(B52, "MMMM YYYY") -> January 2026 | I52: =D52*E52 -> 225 | J52: =E52*30 -> 150 | K52: =IF(F52=I52,TRUE) -> TRUE
...

Sheet Dec 2025 Sales
A1: Timestamp | B1: Sales Date | C1: Customer name | D1: Product type | E1: Quantity | F1: Unit Price | G1: Payment Method | H1: Delivery Method | I1: Total | J1: Column 1
A2: 46038.613 | B2: 46022 | C2: Farmer | D2: Layer | E2: 15 | F2: 60 | G2: Cash | H2: Pick up | I2: =E2*F2 -> 900 | J2: TEI | L2: TEI | M2: =SUMIF(J:J,L2,I:I) -> 46520
A3: 46038.613 | B3: 46022 | C3: Farmer | D3: Layer | E3: 10 | F3: 50 | G3: Cash | H3: Pick up | I3: =E3*F3 -> 500 | J3: TEI | L3: PERCY | M3: =SUMIF(J:J,L3,I:I) -> 16300
A4: 46026.753 | B4: 46022 | C4: Farmer @Kotoku | D4: Layer | E4: 20 | F4: 60 | G4: Cash | H4: Delivery | I4: =E4*F4 -> 1200 | J4: TEI | L4: ENT | M4: =SUMIF(J:J,L4,I:I) -> 11310
A5: 46026.754 | B5: 46022 | C5: Farmer @Kotoku | D5: Layer | E5: 10 | F5: 45 | G5: Cash | H5: Delivery | I5: =E5*F5 -> 450 | J5: TEI | M5: =M2+M3+M4 -> 74130
A6: 46024.507 | B6: 46022 | C6: Auntie Doris | D6: Broiler | E6: 2 | F6: 250 | G6: Cash | H6: Delivery | I6: =E6*F6 -> 500 | J6: TEI
A7: 46024.507 | B7: 46022 | C7: Auntie Evelyn | D7: Broiler | E7: 2 | F7: 250 | G7: Cash | H7: Delivery | I7: =E7*F7 -> 500 | J7: TEI
A8: 46024.508 | B8: 46022 | C8: Bro John | D8: Broiler | E8: 1 | F8: 250 | G8: Cash | H8: Delivery | I8: =E8*F8 -> 250 | J8: TEI
A9: 46024.508 | B9: 46022 | C9: Christiana Attafuah | D9: Broiler | E9: 2 | F9: 250 | G9: Cash | H9: Delivery | I9: =E9*F9 -> 500 | J9: TEI
A10: 46024.509 | B10: 46022 | C10: Grandma moda | D10: Broiler | E10: 1 | F10: 250 | G10: Cash | H10: Delivery | I10: =E10*F10 -> 250 | J10: TEI
A11: 46024.508 | B11: 46022 | C11: Mercy | D11: Broiler | E11: 1 | F11: 250 | G11: Cash | H11: Delivery | I11: =E11*F11 -> 250 | J11: TEI
A12: 46024.507 | B12: 46022 | C12: Rev Elliot | D12: Broiler | E12: 2 | F12: 250 | G12: Cash | H12: Delivery | I12: =E12*F12 -> 500 | J12: TEI
A13: 46015.362 | B13: 46022 | C13: Mama lit | D13: Layer | E13: 2 | F13: 100 | G13: Cash | H13: Delivery | I13: =E13*F13 -> 200 | J13: PERCY
A14: 46015.362 | B14: 46022 | C14: Mama lit | D14: Broiler | E14: 4 | F14: 250 | G14: Cash | H14: Delivery | I14: =E14*F14 -> 1000 | J14: PERCY
A15: 46015.362 | B15: 46022 | C15: Percy | D15: Broiler | E15: 6 | F15: 250 | G15: Cash | H15: Delivery | I15: =E15*F15 -> 1500 | J15: PERCY
A16: 46018.197 | B16: 46017 | C16: Bro Atta | D16: Broiler | E16: 1 | F16: 250 | G16: Cash | H16: Delivery | I16: =E16*F16 -> 250 | J16: TEI
A17: 46018.196 | B17: 46017 | C17: Joe | D17: Broiler | E17: 2 | F17: 200 | G17: Cash | H17: Delivery | I17: =E17*F17 -> 400 | J17: TEI
... A94: 46046.457 | B94: 46022 | C94: Naa Amerley | D94: Layer | E94: 10 | F94: 60 | G94: Cash | H94: Delivery | I94: =E94*F94 -> 600 | J94: PERCY
A98: Total | I98: =SUM(Form_Responses2[Total]) -> 74130

Sheet Form responses 11
A1: Timestamp | B1: Sales Date | C1: Customer name | D1: Product type | E1: Quantity | F1: Unit Price | G1: Delivery Method | H1: Payment Method
A2: 45743.104 | B2: 45742 | C2: Maa j | E2: 1 | F2: 220 | G2: Delivery
A3: 45743.104 | B3: 45742 | C3: Mummy | E3: 1 | F3: 220 | G3: Pick up
A4: 45744.734 | B4: 45744 | C4: Genevieve korle bu | E4: 3 | F4: 220 | G4: Delivery
A5: 45745.435 | B5: 45745 | C5: Prince CBG | E5: 4 | F5: 250 | G5: Delivery
A6: 45748.201 | B6: 45748 | C6: Mummy | E6: 2 | F6: 200 | G6: Delivery
A7: 45748.626 | B7: 45748 | C7: Naa Dedei | E7: 1 | F7: 220 | G7: Delivery
A8: 45748.627 | B8: 45748 | C8: Maame Dede | E8: 2 | F8: 220 | G8: Delivery
A9: 45749.923 | B9: 45749 | C9: Benedicta | E9: 5 | F9: 250 | G9: Delivery
A10: 45750.388 | B10: 45750 | C10: Bro Kofi | E10: 2 | F10: 220 | G10: Delivery
A11: 45753.556 | B11: 45753 | C11: Emefa Onyinase | E11: 1 | F11: 220 | G11: Delivery | H11: Mobile
A12: 45753.644 | B12: 45753 | C12: Fiifi sage | E12: 2 | F12: 250 | G12: Delivery | H12: Cash
A13: 45758.598 | B13: 45758 | C13: Agege old lady | E13: 2 | F13: 220 | G13: Delivery | H13: Cash
A14: 45760.755 | B14: 45760 | C14: Sister | E14: 1 | F14: 220 | G14: Delivery | H14: Cash
A15: 45760.755 | B15: 45760 | C15: Tina (Sister) | E15: 4 | F15: 220 | G15: Delivery | H15: Cash
A16: 45761.732 | B16: 45761 | C16: Mummy | E16: 2 | F16: 100 | G16: Pick up | H16: Cash
A17: 45762.316 | B17: 45761 | C17: Sis Adoley | E17: 1 | F17: 200 | G17: Pick up | H17: Cash
A18: 45762.434 | B18: 45762 | C18: Moda | E18: 1 | F18: 220 | G18: Delivery
A19: 45762.52 | B19: 45762 | C19: Ben - Maa J | E19: 3 | F19: 250 | G19: Delivery | H19: Cash
A20: 45763.864 | B20: 45763 | C20: Lady’s Boss | E20: 1 | F20: 220 | G20: Delivery | H20: Cash
A21: 45764.682 | B21: 45764 | C21: Ant Vivian - Sister - Dansoman | E21: 2 | F21: 220 | G21: Delivery | H21: Cash
A22: 45765.148 | B22: 45764 | C22: Rev Class Peters | E22: 1 | F22: 220 | G22: Delivery | H22: Cash
A23: 45765.468 | B23: 45765 | C23: Sinclair | E23: 5 | F23: 220 | G23: Delivery | H23: Mobile
A24: 45765.47 | B24: 45765 | C24: Ant Joyce - Sister Labone | E24: 1 | F24: 220 | G24: Delivery | H24: Cash
A25: 45765.668 | B25: 45764 | C25: Chorkor | E25: 3 | F25: 220 | G25: Delivery | H25: Cash
A26: 45765.668 | B26: 45765 | C26: Patience Spintex | E26: 3 | F26: 220 | G26: Delivery | H26: Cash
A27: 45765.678 | B27: 45765 | C27: Marilyn | E27: 2 | F27: 220 | G27: Delivery | H27: Cash
A28: 45767.578 | B28: 45767 | C28: Belinda | E28: 1 | F28: 220 | G28: Delivery | H28: Cash
A29: 45767.73 | B29: 45767 | C29: Aakaa | E29: 4 | F29: 220 | G29: Delivery | H29: Cash
A30: 45768.328 | B30: 45768 | C30: Bro Atta | E30: 1 | F30: 220 | G30: Pick up | H30: Cash
... A46: 45798.325 | B46: 45797 | C46: Tei | E46: 1 | F46: 200 | G46: Pick up | H46: Cash

Sheet Copy of Mortality and Transfers
A1: Timestamp | B1: Record date | C1: Recorder Name/ID | D1: Were there any mortalities today? | E1: Where did mortality occur | F1: Pen/House/Flock ID (where mortality occurred) | G1: Number of Mortalities | H1: Age/Stage of Birds (at time of mortality) | I1: Enter Age(number) | J1: Suspected Cause(s) of Mortality | K1: Additional Notes on Mortality | L1: Was there any bird movement today? | M1: Type of Movement | N1: Number of Birds Moved | O1: Source Pen/Location ID (from where birds moved) | P1: Destination Pen/Location (to where birds moved) | Q1: Reason for Movement | R1: Additional Notes on Bird Movement
A2: 45798.801 | B2: 45798 | C2: PERCY | D2: Yes | E2: SET A | F2: B46 | G2: 1 | H2: MONTHS | I2: 15 | J2: UKN | K2: It had no fat in it which is good news but it’s too bony and no traits of food Above all it looked like intestines with feaces got burst cos the inner was filled with waste liquid | L2: No
A3: 45799.912 | B3: 45799 | C3: Tei | D3: Yes | E3: SET B | F3: B143 | G3: 1 | H3: WEEKS | I3: 21 | J3: Prolapse | K3: State of prolapse was bad so I had to slaughter it | L3: No
A4: 45801.912 | B4: 45801 | C4: Tei | D4: Yes | E4: SET C | F4: House | G4: 1 | H4: DAYS | I4: 7 | J4: Stampede | K4: Light out overnight | L4: No
A5: 45801.929 | B5: 45801 | C5: Tei | D5: Yes | E5: SET A | F5: B34 | G5: 1 | H5: MONTHS | I5: 15 | J5: Perking | K5: Anal Perking during laying | L5: No
A6: 45805.06 | B6: 45803 | C6: Tei | D6: Yes | E6: SET A | F6: B65 | G6: 1 | H6: MONTHS | I6: 15 | J6: Unknown | L6: No
A7: 45805.063 | B7: 45803 | C7: Tei | D7: Yes | E7: SET B | F7: Pen | G7: 1 | H7: MONTHS | I7: 5 | J7: Prolapse | K7: Administering detox | L7: No
A8: 45805.064 | B8: 45804 | C8: Tei | D8: Yes | E8: SET B | F8: Pen | G8: 1 | H8: MONTHS | I8: 5 | J8: Prolapse | K8: Administering detox | L8: No
A9: 45805.886 | B9: 45805 | C9: Tei | D9: Yes | E9: SET A | F9: B18 | G9: 1 | H9: MONTHS | I9: 15 | J9: Accident/Injury | K9: Its head got stuck overnight | L9: No
A10: 45807.204 | B10: 45806 | C10: Tei | D10: Yes | E10: SET A | F10: QT | G10: 2 | H10: MONTHS | I10: 15 | J10: Unknown | K10: They were weak and have been quarantined for 2 weeks but wasn’t able to recover | L10: No

Sheet Broiler Sales
A1: Timestamp | B1: Sales Date | C1: Customer name | D1: Quantity | E1: Unit Price | F1: Delivery Method | G1: Payment Method | H1: Product type | I1: Total | J1: Amount Banked | K1: Column 1
A2: 45798.325 | B2: 45797 | C2: Tei | D2: 1 | E2: 200 | F2: Pick up | G2: Cash | I2: =D2*E2 -> 200 | J2: 960 | K2: =20*D2 -> 20
A3: 45796.869 | B3: 45795 | C3: Elfreda Agege old lady | D3: 2 | E3: 200 | F3: Delivery | G3: Cash | I3: =D3*E3 -> 400 | K3: =20*D3 -> 40
A4: 45796.868 | B4: 45795 | C4: Bro Atta | D4: 1 | E4: 180 | F4: Pick up | G4: Cash | I4: =D4*E4 -> 180 | K4: =20*D4 -> 20
A5: 45796.867 | B5: 45795 | C5: Mummy | D5: 1 | E5: 180 | F5: Pick up | G5: Cash | I5: =D5*E5 -> 180 | K5: =20*D5 -> 20
A6: 45793.566 | B6: 45793 | C6: David Airport | D6: 3 | E6: 200 | F6: Delivery | G6: Cash | I6: =D6*E6 -> 600 | J6: 600 | K6: =20*D6 -> 60
A7: 45789.43 | B7: 45788 | C7: Naa Dedei | D7: 2 | E7: 180 | F7: Delivery | G7: Cash | I7: =D7*E7 -> 360 | J7: 360 | K7: =20*D7 -> 40
A8: 45784.809 | B8: 45784 | C8: Bro Kofi | D8: 1 | E8: 180 | F8: Pick up | G8: Cash | I8: =D8*E8 -> 180 | J8: =303+1597 -> 1900
A9: 45782.139 | B9: 45781 | C9: Mrs Opara | D9: 1 | E9: 200 | F9: Delivery | G9: Cash | I9: =D9*E9 -> 200 | K9: =20*D9 -> 20
A10: 45782.126 | B10: 45781 | C10: Moda’s Tenant Sapeiman | D10: 1 | E10: 200 | F10: Delivery | G10: Cash | I10: =D10*E10 -> 200 | K10: =20*D10 -> 20
A11: 45780.757 | B11: 45780 | C11: Mama Lee Kwabenya | D11: 1 | E11: 220 | F11: Delivery | G11: Cash | I11: =D11*E11 -> 220 | K11: =20*D11 -> 20
A12: 45777.615 | B12: 45777 | C12: Bro Kofi’s Friend | D12: 1 | E12: 220 | F12: Delivery | G12: Cash | I12: =D12*E12 -> 220 | K12: =20*D12 -> 20
A13: 45776.156 | B13: 45775 | C13: Prince Spintex | D13: 4 | E13: 220 | F13: Delivery | G13: Cash | I13: =D13*E13 -> 880 | K13: =20*D13 -> 80
A14: 45775.157 | B14: 45774 | C14: Moda | D14: 2 | E14: 220 | F14: Delivery | G14: Cash | I14: =D14*E14 -> 440 | J14: 1919 | K14: =20*D14 -> 40
A15: 45773.371 | B15: 45773 | C15: Ewurafua Domeabra | D15: 3 | E15: 220 | F15: Delivery | G15: Cash | I15: =D15*E15 -> 660 | K15: =20*D15 -> 60
A16: 45773.37 | B16: 45773 | C16: Bro Atta | D16: 1 | E16: 200 | F16: Pick up | G16: Cash | I16: =D16*E16 -> 200
A17: 45771.875 | B17: 45771 | C17: Maame Dede | D17: 2 | E17: 220 | F17: Delivery | G17: Cash | I17: =D17*E17 -> 440 | K17: =20*D17 -> 40
A18: 45768.328 | B18: 45768 | C18: Bro Atta | D18: 1 | E18: 220 | F18: Pick up | G18: Cash | I18: =D18*E18 -> 220 | J18: 4913
A19: 45767.73 | B19: 45767 | C19: Aakaa | D19: 4 | E19: 220 | F19: Delivery | G19: Cash | I19: =D19*E19 -> 880 | K19: =20*D19 -> 80
A20: 45767.578 | B20: 45767 | C20: Belinda | D20: 1 | E20: 220 | F20: Delivery | G20: Cash | I20: =D20*E20 -> 220 | K20: =20*D20 -> 20
A21: 45765.678 | B21: 45765 | C21: Marilyn | D21: 2 | E21: 220 | F21: Delivery | G21: Cash | I21: =D21*E21 -> 440 | K21: =20*D21 -> 40
A22: 45765.668 | B22: 45765 | C22: Patience Spintex | D22: 3 | E22: 220 | F22: Delivery | G22: Cash | I22: =D22*E22 -> 660 | J22: =60 -> 60 | K22: =20*D22 -> 60
A23: 45765.668 | B23: 45764 | C23: Chorkor | D23: 3 | E23: 220 | F23: Delivery | G23: Cash | I23: =D23*E23 -> 660 | J23: 660 | K23: =20*D23 -> 60
A24: 45765.47 | B24: 45765 | C24: Ant Joyce - Sister Labone | D24: 1 | E24: 220 | F24: Delivery | G24: Cash | I24: =D24*E24 -> 220 | K24: =20*D24 -> 20
A25: 45765.468 | B25: 45765 | C25: Sinclair | D25: 5 | E25: 220 | F25: Delivery | G25: Mobile | I25: =D25*E25 -> 1100 | K25: =20*D25 -> 100
A26: 45765.148 | B26: 45764 | C26: Rev Class Peters | D26: 1 | E26: 220 | F26: Delivery | G26: Cash | I26: =D26*E26 -> 220 | K26: =20*D26 -> 20
A27: 45764.682 | B27: 45764 | C27: Ant Vivian - Sister - Dansoman | D27: 2 | E27: 220 | F27: Delivery | G27: Cash | I27: =D27*E27 -> 440 | K27: =20*D27 -> 40
A28: 45763.864 | B28: 45763 | C28: Lady’s Boss | D28: 1 | E28: 220 | F28: Delivery | G28: Cash | I28: =D28*E28 -> 220 | K28: =20*D28 -> 20
A29: 45762.52 | B29: 45762 | C29: Ben - Maa J | D29: 3 | E29: 250 | F29: Delivery | G29: Cash | I29: =D29*E29 -> 750 | K29: =20*D29 -> 60
A30: 45762.434 | B30: 45762 | C30: Moda | D30: 1 | E30: 220 | F30: Delivery | G30: Cash | I30: =D30*E30 -> 220 | J30: 2378 | K30: =20*D30 -> 20
A31: 45762.316 | B31: 45761 | C31: Sis Adoley | D31: 1 | E31: 200 | F31: Pick up | G31: Cash | I31: =D31*E31 -> 200
A32: 45761.732 | B32: 45761 | C32: Mummy | D32: 2 | E32: 100 | F32: Pick up | G32: Cash | I32: =D32*E32 -> 200
A33: 45760.755 | B33: 45760 | C33: Tina (Sister) | D33: 4 | E33: 220 | F33: Delivery | G33: Cash | I33: =D33*E33 -> 880 | K33: =20*D33 -> 80
A34: 45760.755 | B34: 45760 | C34: Sister | D34: 1 | E34: 220 | F34: Delivery | G34: Cash | I34: =D34*E34 -> 220 | K34: =20*D34 -> 20
A35: 45758.598 | B35: 45758 | C35: Agege old lady | D35: 2 | E35: 220 | F35: Delivery | G35: Cash | I35: =D35*E35 -> 440 | K35: =20*D35 -> 40
A36: 45753.644 | B36: 45753 | C36: Fiifi sage | D36: 2 | E36: 250 | F36: Delivery | G36: Cash | I36: =D36*E36 -> 500 | J36: 4320 | K36: =20*D36 -> 40
A37: 45753.556 | B37: 45753 | C37: Emefa Onyinase | D37: 1 | E37: 220 | F37: Delivery | G37: Mobile | I37: =D37*E37 -> 220 | K37: =20*D37 -> 20
A38: 45750.388 | B38: 45750 | C38: Bro Kofi | D38: 2 | E38: 220 | F38: Delivery | G38: Cash | I38: =D38*E38 -> 440 | K38: =20*D38 -> 40
A39: 45749.923 | B39: 45749 | C39: Benedicta | D39: 5 | E39: 250 | F39: Delivery | G39: Bank | I39: =D39*E39 -> 1250 | J39: =I39 -> 1250 | K39: =20*D39 -> 100
A40: 45748.627 | B40: 45748 | C40: Maame Dede | D40: 2 | E40: 220 | F40: Delivery | G40: Cash | I40: =D40*E40 -> 440 | K40: =20*D40 -> 40
...

Sheet Broiler Orders
A1: Timestamp | B1: Order date | C1: Customer Name | D1: Quantity | E1: Delivery date | F1: Delivery Location | G1: Payment Status | H1: Chicken Type | I1: Customer contact | J1: Delivery Status | K1: Comments
A2: 46007.764 | B2: 46003 | C2: Grandma Mother | D2: 1 | E2: 46007 | F2: Opah | G2: On-Delivery | H2: Broiler | I2: 267269919 | J2: Pending
A3: 46015.548 | B3: 46015 | C3: Aakaa | D3: 2 | E3: 46015 | F3: Abeka | G3: On-Delivery | H3: Layer | I3: Tbd | J3: Delivered
A4: 46011.534 | B4: 46011 | C4: Lady | D4: 2 | E4: 46013 | F4: Lapaz | G4: On-Delivery | H4: Broiler | I4: 553134447 | J4: Pending
A5: 46008.276 | B5: 46008 | C5: Aakaa | D5: 8 | E5: 46014 | F5: Abeka | G5: Paid | H5: Broiler | I5: 269710510 | J5: Delivered
A6: 46010.22 | B6: 46010 | C6: Agege | D6: 6 | E6: 46010 | F6: Dansoman | G6: On-Delivery | H6: Layer | I6: 026 222 1212 | J6: Delivered
A7: 46008.281 | B7: 46008 | C7: Adwoa | D7: 1 | E7: 46010 | F7: Lapaz | G7: Paid | H7: Broiler | I7: 546918667 | J7: Delivered
A8: 46011.104 | B8: 46011 | C8: Afia Bortey | D8: 2 | E8: 46013 | F8: Pokuase | G8: On-Delivery | H8: Broiler | I8: 244449517 | J8: Delivered
A9: 46008.282 | B9: 46008 | C9: Augustina | D9: 1 | E9: 46010 | F9: Osu | G9: Paid | H9: Layer | I9: 268871851 | J9: Delivered
A10: 46010.217 | B10: 46010 | C10: Agege Dansoman/ Tei | D10: 2 | E10: 46010 | F10: Dansoman | G10: On-Delivery | H10: Broiler | I10: 262221212 | J10: Delivered
A11: 46008.607 | B11: 46008 | C11: Aunt Mabel | D11: 3 | E11: 46010 | F11: East Legon | G11: On-Delivery | H11: Layer | I11: ‪+1 (404) 388‑6448‬ | J11: Delivered
A12: 46007.77 | B12: 46003 | C12: Amin | D12: 15 | E12: 46010 | F12: Airport | G12: On-Delivery | H12: Broiler | I12: 541094876 | J12: Delivered | K12: 5 boxes
A13: 46008.281 | B13: 46008 | C13: Augustina | D13: 1 | E13: 46010 | F13: Osu | G13: Paid | H13: Broiler | I13: 268871851 | J13: Delivered
A14: 46008.607 | B14: 46008 | C14: Aunt Mabel | D14: 3 | E14: 46010 | F14: East Legon | G14: On-Delivery | H14: Broiler | I14: ‪+1(404)3886448‬ | J14: Delivered
A15: 46012.741 | B15: 46012 | C15: Auntie Doris | D15: 3 | E15: 46013 | F15: Pokuase | G15: Paid | H15: Broiler | I15: =233277773889 -> 233277773889 | J15: Delivered
A16: 46010.199 | B16: 46010 | C16: Auntie Gina | D16: 2 | E16: 46013 | F16: Ashongman | G16: On-Delivery | H16: Broiler | I16: 267269919 | J16: Delivered
C17: Auntie Evelyn | D17: 2 | H17: Broiler | J17: Delivered
C18: Naa Celebrity | D18: 1 | H18: Broiler | J18: Delivered
C19: Mercy | D19: 1 | H19: Broiler | J19: Delivered
C20: Bro John | D20: 1 | H20: Broiler | J20: Delivered
A21: 46007.771 | B21: 46003 | C21: Auntie Gina | D21: 1 | E21: 46010 | F21: Lapaz | G21: On-Delivery | H21: Broiler | I21: 267269919 | J21: Delivered
A22: 46011.104 | B22: 46011 | C22: Belinda Koranteng | D22: 5 | E22: 46013 | F22: Lapaz | G22: On-Delivery | H22: Broiler | I22: +233 54 333 3589 | J22: Delivered
A23: 46010.457 | B23: 46010 | C23: Bro Dk | D23: 2 | E23: 46014 | F23: Lapaz | G23: On-Delivery | H23: Layer | I23: 267269919 | J23: Delivered
A24: 46008.279 | B24: 46008 | C24: Bro Amos | D24: 2 | E24: 46014 | F24: Kotoku | G24: On-Delivery | H24: Broiler | I24: 243010450 | J24: Delivered
A25: 46010.2 | B25: 46010 | C25: Bro DK | D25: 2 | E25: 46014 | F25: Lapaz | G25: On-Delivery | H25: Layer | I25: 77744465 | J25: Delivered
A26: 46010.457 | B26: 46010 | C26: Bro Dk | D26: 4 | E26: 46014 | F26: Lapaz | G26: On-Delivery | H26: Broiler | I26: 267269919 | J26: Delivered
A27: 46008.28 | B27: 46008 | C27: Bro Dk | D27: 2 | E27: 46014 | F27: Lapaz | G27: On-Delivery | H27: Broiler | I27: 277338536 | J27: Delivered
A28: 46013.356 | B28: 46010 | C28: Bro kofi | D28: 2 | E28: 46011 | F28: Kotoku | G28: Paid | H28: Broiler | I28: Tbd | J28: Delivered
A29: 46009.529 | B29: 46009 | C29: Christiana Attafuah | D29: 8 | E29: 46014 | F29: Omanjor D/A | G29: Pending | H29: Broiler | I29: +233 20 418 5566 | J29: Delivered
A30: 46014.17 | B30: 46003 | C30: Derrick | D30: 3 | E30: 46014 | F30: Bubiashie | G30: On-Delivery | H30: Layer | I30: 665 | J30: Pending
A31: 46011.514 | B31: 46011 | C31: Class Peters | D31: 5 | E31: 46013 | F31: Kasoa | G31: On-Delivery | H31: Broiler | I31: 243746751 | J31: Delivered
A32: 46013.257 | B32: 46003 | C32: corners- nsumfa | D32: 3 | E32: 46016 | F32: Tbd | G32: On-Delivery | H32: Broiler | I32: Tbd | J32: Delivered
A33: 46013.257 | B33: 46003 | C33: Edwin CBG | D33: 1 | E33: 46016 | F33: Tbd | G33: On-Delivery | H33: Broiler | I33: Tbd | J33: Delivered | K33: All cut
A34: 46008.278 | B34: 46008 | C34: Ellis Amuzu | D34: 10 | E34: 46010 | F34: Lapaz | G34: On-Delivery | H34: Broiler | I34: 265061724 | J34: Delivered | K34: 5 boxes
A35: 46008.336 | B35: 46008 | C35: Emefa | D35: 6 | E35: 46010 | F35: 3 locations | G35: Paid | H35: Broiler | I35: 0246973448-6 | J35: Delivered
A36: 46008.238 | B36: 46008 | C36: Enterprise Life | D36: 87 | E36: 45999 | F36: Dzorwulu | G36: Paid | H36: Broiler | I36: 243025315 | J36: Delivered
A37: 46008.606 | B37: 46008 | C37: Grandma Bishop | D37: 3 | E37: 46010 | F37: Korle bu | G37: On-Delivery | H37: Layer | I37: 243025315 | J37: Delivered
A38: 46008.283 | B38: 46008 | C38: Eric Gyan | D38: 7 | E38: 46014 | F38: Lapaz | G38: On-Delivery | H38: Broiler | I38: 555249425 | J38: Delivered
A39: 46012.472 | B39: 46012 | C39: Freda yeboah | D39: 2 | E39: 46013 | F39: Korle gonno | G39: On-Delivery | H39: Broiler | I39: +233 27 204 6771 | J39: Delivered | K39: Cut one
A40: 46008.605 | B40: 46008 | C40: Grandma bishop | D40: 3 | E40: 46010 | F40: Korle bu | G40: On-Delivery | H40: Broiler | I40: 243025315 | J40: Delivered
...

Sheet Mortality and Transfers
A1: Timestamp | B1: Mortality/Transfer date | C1: Recorder Name/ID | D1: Select record type | E1: Were there any mortalities today? | F1: Where did mortality occur | G1: Pen/House/Flock ID (where mortality occurred) | H1: Number of Mortalities | I1: Age/Stage of Birds (at time of mortality) | J1: Enter Age(number) | K1: Suspected Cause(s) of Mortality | L1: Additional Notes on Mortality | M1: Inventory Updated? | N1: Type of Movement | O1: Number of Birds Moved | P1: Source Pen/Location ID (from where birds moved) | Q1: Destination Pen/Location (to where birds moved) | R1: Reason for Movement | S1: Additional Notes on Bird Movement
A2: 46051.518 | B2: 45957 | C2: Tei | D2: Mortality | F2: SET B | G2: B174, 283 | H2: 2 | I2: MONTHS | J2: 8 | K2: Unknown
A3: 46051.513 | B3: 45956 | C3: Tei | D3: Mortality | F3: SET A | G3: W48 | H3: 1 | I3: MONTHS | J3: 19 | K3: Prolapse
A4: 46051.514 | B4: 45956 | C4: Tei | D4: Mortality | F4: SET B | G4: B299 | H4: 1 | I4: MONTHS | J4: 8 | K4: Pecking
A5: 46051.512 | B5: 45955 | C5: Tei | D5: Mortality | F5: SET B | G5: W105 | H5: 1 | I5: MONTHS | J5: 8 | K5: Prolapse
A6: 46051.406 | B6: 45954 | C6: Tei | D6: Mortality | F6: SET A | G6: B1 | H6: 1 | I6: MONTHS | J6: 19 | K6: Disease (specify in notes) | L6: Egg Yolk Peritonitis
A7: 46051.408 | B7: 45954 | C7: Tei | D7: Mortality | F7: SET B | G7: B214, 158 | H7: 2 | I7: MONTHS | J7: 8 | K7: Pecking
A8: 46051.402 | B8: 45953 | C8: Tei | D8: Mortality | F8: SET A | G8: B29 | H8: 1 | I8: MONTHS | J8: 19 | K8: Pecking
A9: 46051.402 | B9: 45953 | C9: Tei | D9: Mortality | F9: SET B | G9: W64 | H9: 1 | I9: MONTHS | J9: 8 | K9: Prolapse
A10: 46051.405 | B10: 45953 | C10: Tei | D10: Mortality | F10: SET D | G10: House | H10: 85 | I10: WEEKS | J10: 3 | K10: Predator Attack | L10: Stampede due to predator attack
A11: 46051.344 | B11: 45952 | C11: Tei | D11: Mortality | F11: SET A | G11: W51 | H11: 1 | I11: MONTHS | J11: 19 | K11: Disease (specify in notes) | L11: Egg Yolk Peritonitis
A12: 46051.345 | B12: 45952 | C12: Tei | D12: Mortality | F12: SET B | G12: W26, W83 | H12: 2 | I12: MONTHS | J12: 8 | K12: Mites Infestation
A13: 46051.256 | B13: 45951 | C13: Tei | D13: Mortality | F13: SET A | G13: B16, 19, 32 | H13: 3 | I13: MONTHS | J13: 19 | K13: Disease (specify in notes) | L13: Egg Yolk Peritonitis
A14: 46051.257 | B14: 45951 | C14: Tei | D14: Mortality | F14: SET B | G14: W4, B211, 8 | H14: 3 | I14: MONTHS | J14: 8 | K14: Mites Infestation
A15: 46051.104 | B15: 45950 | C15: Tei | D15: Mortality | F15: SET B | G15: B57 | H15: 1 | I15: MONTHS | J15: 8 | K15: Pecking
A16: 46051.103 | B16: 45949 | C16: Tei | D16: Mortality | F16: SET A | G16: B65 | H16: 1 | I16: MONTHS | J16: 19 | K16: Disease (specify in notes) | L16: Egg Yolk Peritonitis
A17: 46051.096 | B17: 45948 | C17: Tei | D17: Mortality | F17: SET A | G17: W6 | H17: 1 | I17: MONTHS | J17: 19 | K17: Pecking
A18: 46051.098 | B18: 45948 | C18: Tei | D18: Mortality | F18: SET B | G18: W91 | H18: 1 | I18: MONTHS | J18: 8 | K18: Pecking
A19: 46051.095 | B19: 45947 | C19: Tei | D19: Mortality | F19: SET B | G19: W78 | H19: 1 | I19: MONTHS | J19: 8 | K19: Unknown
A20: 46050.607 | B20: 45946 | C20: Tei | D20: Mortality | F20: SET A | G20: B3 | H20: 1 | I20: MONTHS | J20: 19 | K20: Pecking
A21: 46050.609 | B21: 45946 | C21: Tei | D21: Mortality | F21: SET B | G21: B243, 158, W82 | H21: 3 | I21: MONTHS | J21: 8 | K21: Pecking
A22: 46050.603 | B22: 45944 | C22: Tei | D22: Mortality | F22: SET B | G22: B52, B195 | H22: 2 | I22: MONTHS | J22: 8 | K22: Mites infestation
A23: 46050.599 | B23: 45943 | C23: Tei | D23: Mortality | F23: SET A | G23: W38 | H23: 1 | I23: MONTHS | J23: 19 | K23: Prolapse
A24: 46050.602 | B24: 45943 | C24: Tei | D24: Mortality | F24: SET B | G24: W45 | H24: 1 | I24: MONTHS | J24: 8 | K24: Mites infestation
A25: 46050.587 | B25: 45941 | C25: Tei | D25: Mortality | F25: SET B | G25: B55 | H25: 1 | I25: MONTHS | J25: 8 | K25: Prolapse
A26: 46050.581 | B26: 45940 | C26: Tei | D26: Mortality | F26: SET A | G26: B57 | H26: 1 | I26: MONTHS | J26: 19 | K26: Pecking
A27: 46050.582 | B27: 45940 | C27: Tei | D27: Mortality | F27: SET B | G27: W78 | H27: 1 | I27: MONTHS | J27: 8 | K27: Pecking
A28: 46050.576 | B28: 45939 | C28: Tei | D28: Mortality | F28: SET A | G28: W1, 7,27,39,48, B26,43,51,72 | H28: 9 | I28: MONTHS | J28: 19 | K28: Mites infestation
... A35: 46050.447 | B35: 45933 | C35: Tei | D35: Mortality | F35: SET B | G35: W1, B134 | H35: 2 | I35: MONTHS | J35: 8 | K35: Prolapse
A36: 46050.397 | B36: 45931 | C36: Tei | D36: Mortality | F36: SET A | G36: W22, W48 | H36: 2 | I36: MONTHS | J36: 8 | K36: Disease (specify in notes) | L36: Wry Neck (twisting neck)
A37: 46050.398 | B37: 45931 | C37: Tei | D37: Mortality | F37: SET B | G37: B65, W83 | H37: 2 | I37: MONTHS | J37: 8 | K37: Pecking
A38: 46050.405 | B38: 45931 | C38: Tei | D38: Mortality | F38: SET D | G38: House | H38: 1 | I38: DAYS | J38: 2 | K38: Accident/Injury
A39: 46050.393 | B39: 45930 | C39: Tei | D39: Mortality | F39: SET B | G39: B143 | H39: 1 | I39: MONTHS | J39: 8 | K39: Mites
A40: 46050.404 | B40: 45930 | C40: Tei | D40: Mortality | F40: SET D | G40: House | H40: 2 | I40: DAYS | J40: 1 | K40: Accident/Injury
A41: 46050.382 | B41: 45929 | C41: Tei | D41: Mortality | F41: SET A | G41: B51 | H41: 1 | I41: MONTHS | J41: 19 | K41: Pecking
A42: 46050.383 | B42: 45929 | C42: Tei | D42: Mortality | F42: SET B | G42: B269 | H42: 1 | I42: MONTHS | J42: 8 | K42: Pecking
A43: 46050.322 | B43: 45928 | C43: Tei | D43: Mortality | F43: SET B | G43: W89, B301 | H43: 2 | I43: MONTHS | J43: 8 | K43: Mites infestation
A44: 46050.297 | B44: 45927 | C44: Tei | D44: Mortality | F44: SET A | G44: W56 | H44: 1 | I44: MONTHS | J44: 19 | K44: Looking Weak
A45: 46050.314 | B45: 45927 | C45: Tei | D45: Mortality | F45: SET B | G45: W96 | H45: 1 | I45: MONTHS | J45: 8 | K45: Pecking
A46: 46050.295 | B46: 45926 | C46: Tei | D46: Mortality | F46: SET B | G46: B288, B113, W77 | H46: 3 | I46: MONTHS | J46: 8 | K46: Pecking
...

Sheet Stock trace
A1: Timestamp | B1: Event Type | C1: Coop/Cage | D1: Quantity | E1: Details | F1: Action taken | G1: Remarks | H1: SET
A2: 45797.842 | B2: Mortality | C2: Cage | D2: 12 | E2: Excess fat | F2: Investigated cause | G2: Treating Fatty Acid Syndrome by detoxing | H2: LAYER SET A | I2: Mortality Summary | J2: LAYER SET A | K2: =SUMIF(H2:H2001,J2,D2:D2001) -> 42
A3: 45779.897 | B3: Mortality | C3: Coop | D3: 1 | E3: Stress | F3: Investigated cause | G3: Stampede | H3: LAYER SET B
A4: 45779.896 | B4: Mortality | C4: Cage | D4: 1 | E4: Stress | F4: Investigated cause | G4: Perking and Panicking | H4: LAYER SET A
A5: 45777.289 | B5: Mortality | C5: Cage | D5: 5 | E5: Stress | F5: Inspected health | G5: Still stepping on themselves, we stay there for long to prevent that but we still woke up to these mortalities | H5: LAYER SET A
A6: 45777.264 | B6: Mortality | C6: Cage | D6: 5 | E6: Stress | F6: Inspected health | G6: They keep standing on each other which bursts the yokes in them and causes infection | H6: LAYER SET A
A7: 45777.259 | B7: Mortality | C7: Coop | D7: 1 | E7: Stress | F7: Inspected health | G7: Stampede from rain | H7: LAYER SET B
A8: 45774.127 | B8: Mortality | C8: Cage | D8: 4 | E8: Stress | F8: Investigated cause | G8: Stress from construction | H8: LAYER SET A
A9: 45771.337 | B9: Mortality | C9: Cage | D9: 3 | E9: Stress | F9: Investigated cause | G9: Perking and egg-binding(dystopia). Selective Debeaking will be done and administering of lasota to help produce more healthy eggs | H9: LAYER SET A
A10: 45766.102 | B10: Mortality | C10: Coop | D10: 3 | E10: Stress | F10: Inspected health | G10: Overweight stress | H10: BROILER
A11: 45756.049 | B11: Mortality | C11: Cage | D11: 10 | E11: Disease | F11: Treatment initiated | G11: Mites infestation which was treated by using cypervet | H11: LAYER SET A
A12: 45756.045 | B12: Mortality | C12: Coop | D12: 6 | E12: Stress | F12: Treatment initiated | G12: Feed reduction at a point, visiting often to rectify falling on back issues | H12: BROILER
A13: 45756.034 | B13: Mortality | C13: Coop | D13: 2 | E13: Stress | F13: Investigated cause | G13: Stress from debeaking | H13: LAYER SET B
A14: 45756.033 | B14: Mortality | C14: Coop | D14: 40 | E14: Stress | F14: Investigated cause | G14: Avoid overcrowding during vaccinations to prevent stampede | H14: LAYER SET B
A15: 45734.323 | B15: Mortality | C15: W22/WQT | D15: 2 | E15: Disease | F15: Treatment initiated | G15: Sent them to the vet for post-mortem and they found mites on them so they're on medication now. | H15: LAYER SET A | I15: Layer SET A | J15: 430
A16: 45731.328 | B16: Mortality | C16: QT | D16: 1 | E16: Perking | F16: Investigated cause | G16: Under medication
A17: 45731.324 | B17: Mortality | C17: Broiler | D17: 1 | E17: Stress | F17: Treatment initiated | G17: Stress from sawdust change
A18: 45731.315 | B18: Mortality | C18: B2 | D18: 1 | E18: Stress | F18: Inspected health | G18: Medication to be administered
A19: 45727.01 | B19: Mortality | C19: B18 | D19: 1 | E19: Cause unidentified | F19: Inspected health | G19: Need to check they're kidneys and hearts
A20: 45726.973 | B20: Mortality | C20: W | D20: 1 | E20: Prolapse | F20: Inspected health | G20: Was under treatment but couldn't make it out of QT
A21: 45709.452 | B21: Mortality | C21: Broiler | D21: 1 | E21: Stress | F21: Inspected health | G21: Stress from transportation
A22: 45709.45 | B22: Quarantine | C22: B75 | D22: 2 | E22: Excess fat | F22: Treatment initiated | G22: Feed reduced
A23: 45709.443 | B23: Quarantine | C23: B44 | D23: 1 | E23: Paralysis | F23: Treatment initiated | G23: Isolated and taking antibiotic vitamins
A24: 45709.441 | B24: Quarantine | C24: W3 | D24: 1 | E24: Paralysis | F24: Treatment initiated | G24: Isolated and taking antibiotic vitamins
A25: 45709.439 | B25: Mortality | C25: SET 1 | D25: 4 | E25: Excess fat | F25: Investigated cause | G25: Measures like reduction in feed and detoxification is Being taken
A26: 45709.387 | B26: Mortality | C26: SET 2 | D26: 17 | E26: Perking | F26: Treatment initiated | G26: Mixed salt with their feed

Sheet Request Form
A1: Timestamp | B1: Item Name | C1: Quantity | D1: Price | E1: Due Date | F1: Purpose
A2: 45680.052 | B2: Day-Old Feeders | C2: 5 | E2: 45658 | F2: Farm Use
A3: 45680.053 | B3: 10L Drinker | C3: 4 | E3: 45658 | F3: Farm Use
A4: 45710.69 | B4: Feeder - Big | C4: 3 | E4: 45709 | F4: Farm Use
A5: 45710.691 | B5: 10L Drinker | C5: 11 | E5: 45709 | F5: Farm Use
A6: 45710.692 | B6: 10L Drinker | C6: 6 | E6: 45710 | F6: Sale
A7: 45710.692 | B7: Feeder - Big | C7: 6 | E7: 45710 | F7: Sale
A8: 45727.023 | B8: Overall | C8: 2 | E8: 45727 | F8: Farm Use
A9: 45727.023 | B9: Boot | C9: 2 | E9: 45727 | F9: Farm use
B10: big cooler box | C10: 1 | D10: 40 | F10: sale- Bank
B11: small cooler bag | C11: 1 | D11: 40 | F11: sale- Bank

Sheet COS Layers 1
A1: DATE
A2: Timestamp | B2: Item name/Service Description | C2: Service/item category | D2: Quantity | E2: Unit Price | F2: Amount Paid | G2: Column 1
A3: MED
A4: 45772.471 | B4: Lasota Vaccine | C4: Layers - SET 1 | D4: 1 | E4: 100 | F4: 100 | G4: =D4*E4 -> 100
A5: 45771.318 | B5: Postmortem | C5: Layers - SET 1 | D5: 2 | E5: 50 | F5: 100 | G5: =D5*E5 -> 100
A6: 45770.208 | B6: Colvit | C6: Layers - SET 1 | D6: 1 | E6: 175 | F6: 175 | G6: =D6*E6 -> 175
A7: 45750.561 | B7: Postmortem | C7: Layers - SET 1 | D7: 1 | E7: 50 | F7: 50 | G7: =D7*E7 -> 50
A8: 45736.915 | B8: MultiAmino-M 1kg | C8: Layers - SET 1 | D8: 1 | E8: 224 | F8: 224 | G8: =D8*E8 -> 224
A9: 45736.91 | B9: Cypervet 12% 1kg | C9: Layers - SET 1 | D9: 1 | E9: 226 | F9: 226 | G9: =D9*E9 -> 226
A10: 45736.91 | B10: Acalice Super 1kg | C10: Layers - SET 1 | D10: 1 | E10: 80 | F10: 80 | G10: =D10*E10 -> 80
A11: 45734.347 | B11: Med - Dufamec | C11: Layers - SET 1 | D11: 1 | E11: 356 | F11: 356 | G11: =D11*E11 -> 356
A12: 45734.337 | B12: Post-mortem | C12: Layers - SET 1 | D12: 2 | E12: 50 | F12: 100 | G12: =D12*E12 -> 100
A13: 45674.175 | B13: 2nd Gumboro Vaccination | C13: Layers | D13: 1 | E13: 340 | F13: 340 | G13: =D13*E13 -> 340
A14: 45668.451 | B14: Oxytetravet aerosol | C14: Layers | D14: 1 | E14: 78 | F14: 78 | G14: =D14*E14 -> 78
A15: 45665.832 | B15: 1st Gumboro Vaccination | C15: Layers | D15: 1 | E15: 320 | F15: 320 | G15: =D15*E15 -> 320
... A17: 45667.304 | B17: 1st Newcastle Vaccination | C17: Layers | D17: 1 | E17: 270 | F17: 270 | G17: =D17*E17 -> 270
G18: =D18*E18 -> 0
G19: =D19*E19 -> 0
G20: =D20*E20 -> 0
A21: FEED | G21: =D21*E21 -> 0
A22: 45770.204 | B22: Koudijs Layer 2 | C22: Layers - SET 1 | D22: 20 | E22: 424 | F22: 8480 | G22: =D22*E22 -> 8480
A23: 45767.07 | B23: Koudijs layer 2 Mash | C23: Layers - SET 1 | D23: 1 | E23: 424 | F23: 424 | G23: =D23*E23 -> 424
A24: 45752.941 | B24: Koudijs Layer 2 Mash | C24: Layers - SET 1 | D24: 15 | E24: 424 | F24: 6360 | G24: =D24*E24 -> 6360
A25: 45750.368 | B25: Koudijs Layer 2 Mash | C25: Layers - SET 1 | D25: 5 | E25: 424 | F25: 2120 | G25: =D25*E25 -> 2120
A26: 45747.787 | B26: Koudijs Layer 2 Mash | C26: Layers - SET 1 | D26: 2 | E26: 424 | F26: 848 | G26: =D26*E26 -> 848
A27: 45739.004 | B27: Layer 2 Mash | C27: Layers - SET 1 | D27: 10 | E27: 424 | F27: 4240 | G27: =D27*E27 -> 4240
A28: 45736.911 | B28: Layer 2 Mash | C28: Layers - SET 1 | D28: 1 | E28: 424 | F28: 424 | G28: =D28*E28 -> 424
A29: 45736.023 | B29: Layer 2 Mash | C29: Layers - SET 1 | D29: 1 | E29: 424 | F29: 424 | G29: =D29*E29 -> 424
A30: 45727.528 | B30: Layer 2 Mash | C30: Layers - SET 1 | D30: 12 | E30: 424 | F30: 5088 | G30: =D30*E30 -> 5088
A31: 45713.083 | B31: Koudijs Layer 2 Mash | C31: Layers - SET 1 | D31: 12 | E31: 424 | F31: 5088 | G31: =D31*E31 -> 5088
A32: 45702.446 | B32: Koudijs Layer 2 Mash | C32: Layers - SET 1 | D32: 10 | E32: 424 | F32: 4240 | G32: =D32*E32 -> 4240
A33: 45696.565 | B33: Koudijs Layer 2 Mash | C33: Layers - SET 1 | D33: 6 | E33: 424 | F33: 2544 | G33: =D33*E33 -> 2544
... A39: 45668.45 | B39: Layer 1 Mash | C39: Layers | D39: 5 | E39: 414 | F39: 2070 | G39: =D39*E39 -> 2070
G40: =D40*E40 -> 0
G41: =D41*E41 -> 0
G42: =D42*E42 -> 0
G43: =D43*E43 -> 0
A44: OTHERS | G44: =D44*E44 -> 0
A45: 45713.085 | B45: Crates | C45: Layers - SET 1 | D45: 10 | E45: 82 | F45: 820 | G45: =D45*E45 -> 820
A46: 45702.445 | B46: Crates | C46: Layers - SET 1 | D46: 5 | E46: 82 | F46: 410 | G46: =D46*E46 -> 410
...

Sheet PMT Summary
A1: EGG SALES SUMMARY
A2: Total Sales | B2: Amount Banked | C2: Not Banked | D2: MoMo Sales | E2: Cash Sales | F2: Sold(singles) | G2: Sold(crates)
A3: =SUM('Egg Sales'!I:I) -> 604093 | B3: =SUM('Egg Sales'!L:L) -> 600653 | C3: =A3-B3-D3 -> 3440 | D3: =SUMIFS('Egg Sales'!H:H,'Egg Sales'!F:F,"MOMO") -> 0 | E3: =SUMIFS('Egg Sales'!I:I,'Egg Sales'!G:G,"Bank") -> 301286 | F3: =SUM('Egg Sales'!J:J) -> 351420 | G3: =F3/30 -> 11714
A6: EGGS TOTAL INVENTORY
A7: Total Collected | B7: Actual Total | C7: In Stock(singles) | D7: In Stock(Crate) | E7: Damaged(Singles) | F7: Damaged(Crates) | G7: % Damaged
A8: =SUM(Production!J:J) -> 352087 | B8: =F23+B18+F28 -> 344299 | C8: =B8-F3 -> -7121 | D8: =C8/30 -> -237.36667 | E8: =E23+C18+E28+C23 -> 7788 | F8: =E8/30 -> 259.6 | G8: =E8/A8 -> 0.022119533
A11: ACCOUNT SUMMARY
A12: Amount Spent | B12: Amount Issued | C12: Balance | D12: Deposit | E12: TOTAL | F12: REVENUE | G12: Gross Profit
A13: =SUM('Accountable Imprest '!O:O) -> 1332023.2 | B13: =SUM(Imprest!B:B) -> 1304609 | C13: =B13-A13 -> -27414.2 | E13: =C13+D32+C3 -> -23974.2 | F13: =A3+B32+E36+G36 -> 697543 | G13: =F13-A13 -> -634480.2
A16: EGGS INVENTORY SUMMARY - SET A
A17: Total Collected | B17: Actual Total | C17: Damaged(Singles) | D17: Damaged(Crates)
A18: =SUMIF(Production!G:G,"SET A",Production!J:J) -> 118074 | B18: =SUMIF(Production!G:G,"SET A",Production!K:K) -> 115575 | C18: =SUMIF(Production!G:G,"SET A",Production!E:E) -> 2499 | D18: =C18/30 -> 83.3 | E18: =C18/A18 -> 0.021164693
A21: EGGS INVENTORY SUMMARY - SET B
A22: Total Collected | B22: Actual Total | C22: D(singles) | D22: D(crate) | E22: Damaged(Singles) | F22: Actual | G22: % Damaged
A23: =SUMIF(Production!G:G,"SET B",Production!J:J) -> 194908 | B23: =SUMIF(Production!G:G,"SET B",Production!K:K) -> 190508 | C23: =D23*30 -> 240 | D23: 8 | E23: =SUMIF(Production!G:G,"SET B",Production!E:E) -> 4400 | F23: =A23-E23-C23 -> 190268 | G23: =E23/A23 -> 0.022574753
A26: EGGS INVENTORY SUMMARY - SET C
A27: Total Collected | B27: Actual Total | C27: D(singles) | D27: D(crate) | E27: Damaged(Singles) | F27: Actual | G27: % Damaged
A28: =SUMIF(Production!G:G,"SET C",Production!J:J) -> 39105 | B28: =SUMIF(Production!G:G,"SET C",Production!K:K) -> 38456 | C28: =D28*30 -> 0 | D28: 0 | E28: =SUMIF(Production!G:G,"SET C",Production!E:E) -> 649 | F28: =A28-E28-C28 -> 38456 | G28: =E28/A28 -> 0.016596343
A30: BROILER SUMMARY
A31: QTY Sold | B31: TOTAL SALES | C31: Sales Banked | D31: NOT BANKED | E31: LIVE QTY | F31: LIVE QTY | G31: FROZEN QTY
A32: =SUM('Broiler Sales'!D:D) -> 89 | B32: =SUM('Broiler Sales'!I:I) -> 19320 | C32: =SUM('Broiler Sales'!J:J) -> 19320 | D32: =B32-C32 -> 0
A34: XMAS BROILER SUMMARY
A35: Ordered QTY | B35: Total Stock | C35: In Stock | D35: QTY Delivered | E35: Amount Sold | F35: Pending Delivery | G35: Layers SOLD AMT
A36: =SUMIF('Broiler Orders'!H:H,"Broiler",'Broiler Orders'!D:D) -> 304 | B36: =239+40+20+20 -> 319 | C36: =B36-A36 -> 15 | D36: =SUMIF('Dec 2025 Sales'!D:D,"Broiler",'Dec 2025 Sales'!E:E) -> 304 | E36: =SUMIF('Dec 2025 Sales'!D:D,"Broiler",'Dec 2025 Sales'!I:I) -> 63380 | F36: =A36-D36 -> 0 | G36: =SUMIF('Dec 2025 Sales'!D:D,"Layer",'Dec 2025 Sales'!I:I) -> 10750
A38: LAYERS INVENTORY SUMMARY
A39: SET A | B39: SET B | C39: SET C | D39: TOTAL(Laying)
A40: =SUMIF(Stock!C:C,"SET A",Stock!B:B) -> 410 | B40: =SUMIF(Stock!C:C,"SET B",Stock!B:B) -> 1126 | C40: =SUMIF(Stock!C:C,"SET C",Stock!B:B) -> 465 | D40: =SUM(A40:B40) -> 1536
A42: SET A - QTN | B42: SET B - QTN | C42: SET C - QTN | D42: QTN TOTAL
A43: =SUMIF(Stock!C:C,"SET A - Quarantine",Stock!B:B) -> 4 | B43: =SUMIF(Stock!C:C,"SET B - Quarantine",Stock!B:B) -> 0 | C43: =SUMIF(Stock!C:C,"SET C - Quarantine",Stock!B:B) -> 0 | D43: =SUM(A43:C44) -> 4
A46: SET A TOTAL | B46: SET B TOTAL | C46: SET C TOTAL | D46: SET D TOTAL | E46: BROILERS TOTAL | G46: TOTAL
A47: =SUM(A40,A43) -> 414 | B47: =SUM(B40,B43) -> 1126 | C47: =SUM(C40,C43) -> 465 | D47: =Stock!F6 -> 2020 | G47: =SUM(A47:D48) -> 4025
A49: MORTALITY
A50: SET A | B50: SET B | C50: SET C
A51: =SUMIF('Mortality and Transfers'!F:F,"SET A",'Mortality and Transfers'!H:H)/Stock!F3 -> 0.11352657 | B51: =SUMIF('Mortality and Transfers'!F:F,"SET B",'Mortality and Transfers'!H:H)/Stock!F4 -> 0.071428571 | C51: =SUMIF('Mortality and Transfers'!F:F,"SET C",'Mortality and Transfers'!H:H)/Stock!F5 -> 0.077380952
A52: =SUMIF('Mortality and Transfers'!F:F,"SET A",'Mortality and Transfers'!H:H) -> 47 | B52: =SUMIF('Mortality and Transfers'!F:F,"SET B",'Mortality and Transfers'!H:H) -> 82 | C52: =SUMIF('Mortality and Transfers'!F:F,"SET C",'Mortality and Transfers'!H:H) -> 39
A54: Weeks of Age - WOA
A55: SET A | B55: SET B | C55: SET C | D55: SET D | E55: Broilers
A56: =(TODAY()-Stock!F12)/7 -> 103.85714 | B56: =(TODAY()-Stock!F13)/7 -> 58.428571 | C56: =(TODAY()-Stock!F14)/7 -> 37.714286 | D56: =(TODAY()-Stock!F15)/7 -> 19.285714 | E56: =(TODAY()-Stock!F16)/7 -> 16.714286

Sheet MoM Summary
A1: Month | B1: Opening Balance | C1: Total Production | D1: Damaged | E1: Actual | F1: Total Eggs Sold | G1: Closing Balance | H1: Running Total | I1: Total Sales
A2: =TEXT(DATE(2025, ROW(A1), 1), "MMMM YYYY") -> January 2025 | B2: 0 | C2: =SUMIF(Production!L:L, A2, Production!J:J) -> 13491 | D2: =SUMIF(Production!L:L, A2, Production!E:E) -> 226 | E2: =SUMIF(Production!L:L, A2, Production!K:K) -> 13265 | F2: =SUMIF('Egg Sales'!H:H, A2, 'Egg Sales'!J:J) -> 13260 | G2: 5 | H2: =B2+C2 -> 13491 | I2: =SUMIF('Egg Sales'!H:H, A2, 'Egg Sales'!I:I) -> 23503
A3: =TEXT(DATE(2025, ROW(A2), 1), "MMMM YYYY") -> February 2025 | B3: =G2 -> 5 | C3: =SUMIF(Production!L:L, A3, Production!J:J) -> 11792 | D3: =SUMIF(Production!L:L, A3, Production!E:E) -> 167 | E3: =SUMIF(Production!L:L, A3, Production!K:K) -> 11625 | F3: =SUMIF('Egg Sales'!H:H, A3, 'Egg Sales'!J:J) -> 11610 | G3: =B3+E3-F3 -> 20 | H3: =B3+C3 -> 11797 | I3: =SUMIF('Egg Sales'!H:H, A3, 'Egg Sales'!I:I) -> 20687
A4: =TEXT(DATE(2025, ROW(A3), 1), "MMMM YYYY") -> March 2025 | B4: =G3 -> 20 | C4: =SUMIF(Production!L:L, A4, Production!J:J) -> 12333 | D4: =SUMIF(Production!L:L, A4, Production!E:E) -> 191 | E4: =SUMIF(Production!L:L, A4, Production!K:K) -> 12142 | F4: =SUMIF('Egg Sales'!H:H, A4, 'Egg Sales'!J:J) -> 11400 | G4: =B4+E4-F4 -> 762 | H4: =B4+C5 -> 11627 | I4: =SUMIF('Egg Sales'!H:H, A4, 'Egg Sales'!I:I) -> 20559
A5: =TEXT(DATE(2025, ROW(A4), 1), "MMMM YYYY") -> April 2025 | B5: =G4 -> 762 | C5: =SUMIF(Production!L:L, A5, Production!J:J) -> 11607 | D5: =SUMIF(Production!L:L, A5, Production!E:E) -> 197 | E5: =SUMIF(Production!L:L, A5, Production!K:K) -> 11410 | F5: =SUMIF('Egg Sales'!H:H, A5, 'Egg Sales'!J:J) -> 11340 | G5: =B5+E5-F5 -> 832 | H5: =B5+C5 -> 12369 | I5: =SUMIF('Egg Sales'!H:H, A5, 'Egg Sales'!I:I) -> 20555
A6: =TEXT(DATE(2025, ROW(A5), 1), "MMMM YYYY") -> May 2025 | B6: =G5 -> 832 | C6: =SUMIF(Production!L:L, A6, Production!J:J) -> 20419 | D6: =SUMIF(Production!L:L, A6, Production!E:E) -> 1271 | E6: =SUMIF(Production!L:L, A6, Production!K:K) -> 19148 | F6: =SUMIF('Egg Sales'!H:H, A6, 'Egg Sales'!J:J) -> 15990 | G6: =B6+E6-F6 -> 3990 | H6: =B6+C6 -> 21251 | I6: =SUMIF('Egg Sales'!H:H, A6, 'Egg Sales'!I:I) -> 27685
A7: =TEXT(DATE(2025, ROW(A6), 1), "MMMM YYYY") -> June 2025 | B7: =G6 -> 3990 | C7: =SUMIF(Production!L:L, A7, Production!J:J) -> 38028 | D7: =SUMIF(Production!L:L, A7, Production!E:E) -> 970 | E7: =SUMIF(Production!L:L, A7, Production!K:K) -> 37058 | F7: =SUMIF('Egg Sales'!H:H, A7, 'Egg Sales'!J:J) -> 36750 | G7: =(B7+E7)-F7-'PMT Summary'!C23 -> 4058 | H7: =B7+C7 -> 42018 | I7: =SUMIF('Egg Sales'!H:H, A7, 'Egg Sales'!I:I) -> 61456
A8: =TEXT(DATE(2025, ROW(A7), 1), "MMMM YYYY") -> July 2025 | B8: =G7 -> 4058 | C8: =SUMIF(Production!L:L, A8, Production!J:J) -> 37791 | D8: =SUMIF(Production!L:L, A8, Production!E:E) -> 637 | E8: =SUMIF(Production!L:L, A8, Production!K:K) -> 37154 | F8: =SUMIF('Egg Sales'!H:H, A8, 'Egg Sales'!J:J) -> 37590 | G8: =B8+E8-F8 -> 3622 | H8: =B8+C8 -> 41849 | I8: =SUMIF('Egg Sales'!H:H, A8, 'Egg Sales'!I:I) -> 66110
A9: =TEXT(DATE(2025, ROW(A8), 1), "MMMM YYYY") -> August 2025 | B9: =G8 -> 3622 | C9: =SUMIF(Production!L:L, A9, Production!J:J) -> 38340 | D9: =SUMIF(Production!L:L, A9, Production!E:E) -> 547 | E9: =SUMIF(Production!L:L, A9, Production!K:K) -> 37793 | F9: =SUMIF('Egg Sales'!H:H, A9, 'Egg Sales'!J:J) -> 29820 | G9: =B9+E9-F9 -> 11595 | H9: =B9+C9 -> 41962 | I9: =SUMIF('Egg Sales'!H:H, A9, 'Egg Sales'!I:I) -> 55280
A10: =TEXT(DATE(2025, ROW(A9), 1), "MMMM YYYY") -> September 2025 | B10: =G9 -> 11595 | C10: =SUMIF(Production!L:L, A10, Production!J:J) -> 33261 | D10: =SUMIF(Production!L:L, A10, Production!E:E) -> 516 | E10: =SUMIF(Production!L:L, A10, Production!K:K) -> 32745 | F10: =SUMIF('Egg Sales'!H:H, A10, 'Egg Sales'!J:J) -> 39000 | G10: =B10+E10-F10 -> 5340 | H10: =B10+C10 -> 44856 | I10: =SUMIF('Egg Sales'!H:H, A10, 'Egg Sales'!I:I) -> 70285
A11: =TEXT(DATE(2025, ROW(A10), 1), "MMMM YYYY") -> October 2025 | B11: =G10 -> 5340 | C11: =SUMIF(Production!L:L, A11, Production!J:J) -> 36746 | D11: =SUMIF(Production!L:L, A11, Production!E:E) -> 673 | E11: =SUMIF(Production!L:L, A11, Production!K:K) -> 36073 | F11: =SUMIF('Egg Sales'!H:H, A11, 'Egg Sales'!J:J) -> 37500 | G11: =B11+E11-F11 -> 3913 | H11: =B11+C11 -> 42086 | I11: =SUMIF('Egg Sales'!H:H, A11, 'Egg Sales'!I:I) -> 61332
A12: =TEXT(DATE(2025, ROW(A11), 1), "MMMM YYYY") -> November 2025 | B12: =G11 -> 3913 | C12: =SUMIF(Production!L:L, A12, Production!J:J) -> 38195 | D12: =SUMIF(Production!L:L, A12, Production!E:E) -> 654 | E12: =SUMIF(Production!L:L, A12, Production!K:K) -> 37541 | F12: =SUMIF('Egg Sales'!H:H, A12, 'Egg Sales'!J:J) -> 32160 | G12: =B12+E12-F12 -> 9294 | H12: =B12+C12 -> 42108 | I12: =SUMIF('Egg Sales'!H:H, A12, 'Egg Sales'!I:I) -> 53541
A13: =TEXT(DATE(2025, ROW(A12), 1), "MMMM YYYY") -> December 2025 | B13: =G12 -> 9294 | C13: =SUMIF(Production!L:L, A13, Production!J:J) -> 33909 | D13: =SUMIF(Production!L:L, A13, Production!E:E) -> 728 | E13: =SUMIF(Production!L:L, A13, Production!K:K) -> 33181 | F13: =SUMIF('Egg Sales'!H:H, A13, 'Egg Sales'!J:J) -> 40470 | G13: =B13+E13-F13 -> 2005 | H13: =B13+C13 -> 43203 | I13: =SUMIF('Egg Sales'!H:H, A13, 'Egg Sales'!I:I) -> 66410
A14: =TEXT(DATE(2025, ROW(A13), 1), "MMMM YYYY") -> January 2026 | B14: =G13 -> 2005 | C14: =SUMIF(Production!L:L, A14, Production!J:J) -> 25311 | D14: =SUMIF(Production!L:L, A14, Production!E:E) -> 744 | E14: =SUMIF(Production!L:L, A14, Production!K:K) -> 24567 | F14: =SUMIF('Egg Sales'!H:H, A14, 'Egg Sales'!J:J) -> 25080 | G14: =B14+E14-F14 -> 1492 | H14: =B14+C14 -> 27316 | I14: =SUMIF('Egg Sales'!H:H, A14, 'Egg Sales'!I:I) -> 40940
A15: =TEXT(DATE(2025, ROW(A14), 1), "MMMM YYYY") -> February 2026 | B15: =G14 -> 1492 | C15: =SUMIF(Production!L:L, A15, Production!J:J) -> 864 | D15: =SUMIF(Production!L:L, A15, Production!E:E) -> 27 | E15: =SUMIF(Production!L:L, A15, Production!K:K) -> 837 | F15: =SUMIF('Egg Sales'!H:H, A15, 'Egg Sales'!J:J) -> 9450 | G15: =B15+E15-F15 -> -7121 | H15: =B15+C15 -> 2356 | I15: =SUMIF('Egg Sales'!H:H, A15, 'Egg Sales'!I:I) -> 15750
A16: =TEXT(DATE(2025, ROW(A15), 1), "MMMM YYYY") -> March 2026 | B16: =G15 -> -7121 | C16: =SUMIF(Production!L:L, A16, Production!J:J) -> 0 | D16: =SUMIF(Production!L:L, A16, Production!E:E) -> 0 | E16: =SUMIF(Production!L:L, A16, Production!K:K) -> 0 | F16: =SUMIF('Egg Sales'!H:H, A16, 'Egg Sales'!J:J) -> 0 | G16: =B16+E16-F16 -> -7121 | H16: =B16+C16 -> -7121 | I16: =SUMIF('Egg Sales'!H:H, A16, 'Egg Sales'!I:I) -> 0
A17: =TEXT(DATE(2025, ROW(A16), 1), "MMMM YYYY") -> April 2026 | B17: =G16 -> -7121 | C17: =SUMIF(Production!L:L, A17, Production!J:J) -> 0 | D17: =SUMIF(Production!L:L, A17, Production!E:E) -> 0 | E17: =SUMIF(Production!L:L, A17, Production!K:K) -> 0 | F17: =SUMIF('Egg Sales'!H:H, A17, 'Egg Sales'!J:J) -> 0 | G17: =B17+E17-F17 -> -7121 | H17: =B17+C17 -> -7121 | I17: =SUMIF('Egg Sales'!H:H, A17, 'Egg Sales'!I:I) -> 0
A18: =TEXT(DATE(2025, ROW(A17), 1), "MMMM YYYY") -> May 2026 | B18: =G17 -> -7121 | C18: =SUMIF(Production!L:L, A18, Production!J:J) -> 0 | D18: =SUMIF(Production!L:L, A18, Production!E:E) -> 0 | E18: =SUMIF(Production!L:L, A18, Production!K:K) -> 0 | F18: =SUMIF('Egg Sales'!H:H, A18, 'Egg Sales'!J:J) -> 0 | G18: =B18+E18-F18 -> -7121 | H18: =B18+C18 -> -7121 | I18: =SUMIF('Egg Sales'!H:H, A18, 'Egg Sales'!I:I) -> 0
A19: =TEXT(DATE(2025, ROW(A18), 1), "MMMM YYYY") -> June 2026 | B19: =G18 -> -7121 | C19: =SUMIF(Production!L:L, A19, Production!J:J) -> 0 | D19: =SUMIF(Production!L:L, A19, Production!E:E) -> 0 | E19: =SUMIF(Production!L:L, A19, Production!K:K) -> 0 | F19: =SUMIF('Egg Sales'!H:H, A19, 'Egg Sales'!J:J) -> 0 | G19: =B19+E19-F19 -> -7121 | H19: =B19+C19 -> -7121 | I19: =SUMIF('Egg Sales'!H:H, A19, 'Egg Sales'!I:I) -> 0
... A25: =TEXT(DATE(2025, ROW(A24), 1), "MMMM YYYY") -> December 2026 | B25: =G24 -> -7121 | C25: =SUMIF(Production!L:L, A25, Production!J:J) -> 0 | D25: =SUMIF(Production!L:L, A25, Production!E:E) -> 0 | E25: =SUMIF(Production!L:L, A25, Production!K:K) -> 0 | F25: =SUMIF('Egg Sales'!H:H, A25, 'Egg Sales'!J:J) -> 0 | G25: =B25+E25-F25 -> -7121 | H25: =B25+C25 -> -7121 | I25: =SUMIF('Egg Sales'!H:H, A25, 'Egg Sales'!I:I) -> 0
A26: =TEXT(DATE(2025, ROW(A25), 1), "MMMM YYYY") -> January 2027 | B26: =G25 -> -7121
A29: Month | B29: Opening Balance | C29: Total Production | D29: Damaged | E29: Actual | F29: Total Eggs Sold | G29: Closing Balance | H29: Running Total | I29: Total Sales
A30: =TEXT(DATE(2026, ROW(A1), 1), "MMMM") -> January
A31: =TEXT(DATE(2026, ROW(A2), 1), "MMMM") -> February
A32: =TEXT(DATE(2026, ROW(A3), 1), "MMMM") -> March
A33: =TEXT(DATE(2026, ROW(A4), 1), "MMMM") -> April
A34: =TEXT(DATE(2026, ROW(A5), 1), "MMMM") -> May
A35: =TEXT(DATE(2026, ROW(A6), 1), "MMMM") -> June
A36: =TEXT(DATE(2026, ROW(A7), 1), "MMMM") -> July
A37: =TEXT(DATE(2026, ROW(A8), 1), "MMMM") -> August
A38: =TEXT(DATE(2026, ROW(A9), 1), "MMMM") -> September

Sheet Copy of MoM Summary
A1: Month | B1: Opening Balance | C1: Total Production | D1: Damaged | E1: Actual | F1: Total Eggs Sold | G1: Closing Balance | H1: Running Total | I1: Total Sales
A2: =TEXT(DATE(2025, ROW(A1), 1), "MMMM") -> January | B2: 0 | C2: =SUMIF(Production!L:L, A2, Production!J:J) -> 0 | D2: =SUMIF(Production!L:L, A2, Production!E:E) -> 0 | E2: =SUMIF(Production!L:L, A2, Production!K:K) -> 0 | F2: =SUMIF('Egg Sales'!H:H, A2, 'Egg Sales'!J:J) -> 0 | G2: 5 | H2: =B2+C2 -> 0 | I2: =SUMIF('Egg Sales'!H:H, A2, 'Egg Sales'!I:I) -> 0
A3: =TEXT(DATE(2025, ROW(A2), 1), "MMMM") -> February | B3: =G2 -> 5 | C3: =SUMIF(Production!L:L, A3, Production!J:J) -> 0 | D3: =SUMIF(Production!L:L, A3, Production!E:E) -> 0 | E3: =SUMIF(Production!L:L, A3, Production!K:K) -> 0 | F3: =SUMIF('Egg Sales'!H:H, A3, 'Egg Sales'!J:J) -> 0 | G3: =B3+E3-F3 -> 5 | H3: =B3+C3 -> 5 | I3: =SUMIF('Egg Sales'!H:H, A3, 'Egg Sales'!I:I) -> 0
A4: =TEXT(DATE(2025, ROW(A3), 1), "MMMM") -> March | B4: =G3 -> 5 | C4: =SUMIF(Production!L:L, A4, Production!J:J) -> 0 | D4: =SUMIF(Production!L:L, A4, Production!E:E) -> 0 | E4: =SUMIF(Production!L:L, A4, Production!K:K) -> 0 | F4: =SUMIF('Egg Sales'!H:H, A4, 'Egg Sales'!J:J) -> 0 | G4: =B4+E4-F4 -> 5 | H4: =B4+C5 -> 5 | I4: =SUMIF('Egg Sales'!H:H, A4, 'Egg Sales'!I:I) -> 0
A5: =TEXT(DATE(2025, ROW(A4), 1), "MMMM") -> April | B5: =G4 -> 5 | C5: =SUMIF(Production!L:L, A5, Production!J:J) -> 0 | D5: =SUMIF(Production!L:L, A5, Production!E:E) -> 0 | E5: =SUMIF(Production!L:L, A5, Production!K:K) -> 0 | F5: =SUMIF('Egg Sales'!H:H, A5, 'Egg Sales'!J:J) -> 0 | G5: =B5+E5-F5 -> 5 | H5: =B5+C5 -> 5 | I5: =SUMIF('Egg Sales'!H:H, A5, 'Egg Sales'!I:I) -> 0
A6: =TEXT(DATE(2025, ROW(A5), 1), "MMMM") -> May | B6: =G5 -> 5 | C6: =SUMIF(Production!L:L, A6, Production!J:J) -> 0 | D6: =SUMIF(Production!L:L, A6, Production!E:E) -> 0 | E6: =SUMIF(Production!L:L, A6, Production!K:K) -> 0 | F6: =SUMIF('Egg Sales'!H:H, A6, 'Egg Sales'!J:J) -> 0 | G6: =B6+E6-F6 -> 5 | H6: =B6+C6 -> 5 | I6: =SUMIF('Egg Sales'!H:H, A6, 'Egg Sales'!I:I) -> 0
A7: =TEXT(DATE(2025, ROW(A6), 1), "MMMM") -> June | B7: =G6 -> 5 | C7: =SUMIF(Production!L:L, A7, Production!J:J) -> 0 | D7: =SUMIF(Production!L:L, A7, Production!E:E) -> 0 | E7: =SUMIF(Production!L:L, A7, Production!K:K) -> 0 | F7: =SUMIF('Egg Sales'!H:H, A7, 'Egg Sales'!J:J) -> 0 | G7: =(B7+E7)-F7-'PMT Summary'!C23 -> -235 | H7: =B7+C7 -> 5 | I7: =SUMIF('Egg Sales'!H:H, A7, 'Egg Sales'!I:I) -> 0
A8: =TEXT(DATE(2025, ROW(A7), 1), "MMMM") -> July | B8: =G7 -> -235 | C8: =SUMIF(Production!L:L, A8, Production!J:J) -> 0 | D8: =SUMIF(Production!L:L, A8, Production!E:E) -> 0 | E8: =SUMIF(Production!L:L, A8, Production!K:K) -> 0 | F8: =SUMIF('Egg Sales'!H:H, A8, 'Egg Sales'!J:J) -> 0 | G8: =B8+E8-F8 -> -235 | H8: =B8+C8 -> -235 | I8: =SUMIF('Egg Sales'!H:H, A8, 'Egg Sales'!I:I) -> 0
